==========================================
SLURM_JOB_ID = 8153169
SLURM_SUBMIT_DIR = /project/kh_mercury_1
SLURM_JOB_NODELIST = mcn31
==========================================
Job ID: 8153169
Job User: pspahwa
Num Cores: 16
Traceback (most recent call last):
  File "/home/pspahwa/.local/lib/python3.6/site-packages/dask/dataframe/utils.py", line 180, in raise_on_meta_error
    yield
  File "/home/pspahwa/.local/lib/python3.6/site-packages/dask/dataframe/core.py", line 5332, in _emulate
    return func(*_extract_meta(args, True), **_extract_meta(kwargs, True))
  File "/home/pspahwa/.local/lib/python3.6/site-packages/dask/utils.py", line 901, in __call__
    return getattr(obj, self.method)(*args, **kwargs)
  File "/apps/python/3.6/3.6.12/lib/python3.6/site-packages/pandas/core/series.py", line 4213, in apply
    mapped = lib.map_infer(values, f, convert=convert_dtype)
  File "pandas/_libs/lib.pyx", line 2403, in pandas._libs.lib.map_infer
  File "/apps/python/3.6/3.6.12/lib/python3.6/ast.py", line 85, in literal_eval
    return _convert(node_or_string)
  File "/apps/python/3.6/3.6.12/lib/python3.6/ast.py", line 84, in _convert
    raise ValueError('malformed node or string: ' + repr(node))
ValueError: malformed node or string: <_ast.Name object at 0x7fa0bf1c8b00>

The above exception was the direct cause of the following exception:

Traceback (most recent call last):
  File "DirectSearch/updatedDS/possibleNamesDS.py", line 43, in <module>
    main(sys.argv[1], sys.argv[2])
  File "DirectSearch/updatedDS/possibleNamesDS.py", line 32, in main
    firm_df["Possible Names"] = firm_df["Possible Names"].apply(literal_eval)
  File "/home/pspahwa/.local/lib/python3.6/site-packages/dask/dataframe/core.py", line 3368, in apply
    **kwds,
  File "/home/pspahwa/.local/lib/python3.6/site-packages/dask/dataframe/core.py", line 5332, in _emulate
    return func(*_extract_meta(args, True), **_extract_meta(kwargs, True))
  File "/apps/python/3.6/3.6.12/lib/python3.6/contextlib.py", line 99, in __exit__
    self.gen.throw(type, value, traceback)
  File "/home/pspahwa/.local/lib/python3.6/site-packages/dask/dataframe/utils.py", line 201, in raise_on_meta_error
    raise ValueError(msg) from e
ValueError: Metadata inference failed in `apply`.

You have supplied a custom function and Dask is unable to 
determine the type of output that that function returns. 

To resolve this please provide a meta= keyword.
The docstring of the Dask function you ran should have more information.

Original error is below:
------------------------
ValueError('malformed node or string: <_ast.Name object at 0x7fa0bf1c8b00>',)

Traceback:
---------
  File "/home/pspahwa/.local/lib/python3.6/site-packages/dask/dataframe/utils.py", line 180, in raise_on_meta_error
    yield
  File "/home/pspahwa/.local/lib/python3.6/site-packages/dask/dataframe/core.py", line 5332, in _emulate
    return func(*_extract_meta(args, True), **_extract_meta(kwargs, True))
  File "/home/pspahwa/.local/lib/python3.6/site-packages/dask/utils.py", line 901, in __call__
    return getattr(obj, self.method)(*args, **kwargs)
  File "/apps/python/3.6/3.6.12/lib/python3.6/site-packages/pandas/core/series.py", line 4213, in apply
    mapped = lib.map_infer(values, f, convert=convert_dtype)
  File "pandas/_libs/lib.pyx", line 2403, in pandas._libs.lib.map_infer
  File "/apps/python/3.6/3.6.12/lib/python3.6/ast.py", line 85, in literal_eval
    return _convert(node_or_string)
  File "/apps/python/3.6/3.6.12/lib/python3.6/ast.py", line 84, in _convert
    raise ValueError('malformed node or string: ' + repr(node))

srun: error: mcn31: task 0: Exited with exit code 1
