==========================================
SLURM_JOB_ID = 8118516
SLURM_SUBMIT_DIR = /project/kh_mercury_1
SLURM_JOB_NODELIST = mcn03
==========================================
Job ID: 8118516
Job User: pspahwa
Num Cores: 16
Traceback (most recent call last):
  File "/home/pspahwa/.local/lib/python3.6/site-packages/dask/dataframe/utils.py", line 180, in raise_on_meta_error
    yield
  File "/home/pspahwa/.local/lib/python3.6/site-packages/dask/dataframe/core.py", line 5332, in _emulate
    return func(*_extract_meta(args, True), **_extract_meta(kwargs, True))
  File "/home/pspahwa/.local/lib/python3.6/site-packages/dask/utils.py", line 901, in __call__
    return getattr(obj, self.method)(*args, **kwargs)
  File "/apps/python/3.6/3.6.12/lib/python3.6/site-packages/pandas/core/frame.py", line 7552, in apply
    return op.get_result()
  File "/apps/python/3.6/3.6.12/lib/python3.6/site-packages/pandas/core/apply.py", line 185, in get_result
    return self.apply_standard()
  File "/apps/python/3.6/3.6.12/lib/python3.6/site-packages/pandas/core/apply.py", line 276, in apply_standard
    results, res_index = self.apply_series_generator()
  File "/apps/python/3.6/3.6.12/lib/python3.6/site-packages/pandas/core/apply.py", line 305, in apply_series_generator
    results[i] = self.f(v)
  File "DirectSearch/updatedDS/possibleNamesDS.py", line 31, in <lambda>
    news_df["Firms Mentioned"] = news_df.apply(lambda x: find_firms_associated_with_news(x, all_company_lists), axis = 1)
  File "DirectSearch/updatedDS/possibleNamesDS.py", line 17, in find_firms_associated_with_news
    for company_list in all_company_lists:
  File "/home/pspahwa/.local/lib/python3.6/site-packages/dask/dataframe/core.py", line 3060, in __iter__
    s = self.get_partition(i).compute()
  File "/home/pspahwa/.local/lib/python3.6/site-packages/dask/base.py", line 283, in compute
    (result,) = compute(self, traverse=False, **kwargs)
  File "/home/pspahwa/.local/lib/python3.6/site-packages/dask/base.py", line 565, in compute
    results = schedule(dsk, keys, **kwargs)
  File "/home/pspahwa/.local/lib/python3.6/site-packages/dask/threaded.py", line 84, in get
    **kwargs
  File "/home/pspahwa/.local/lib/python3.6/site-packages/dask/local.py", line 487, in get_async
    raise_exception(exc, tb)
  File "/home/pspahwa/.local/lib/python3.6/site-packages/dask/local.py", line 317, in reraise
    raise exc
  File "/home/pspahwa/.local/lib/python3.6/site-packages/dask/local.py", line 222, in execute_task
    result = _execute_task(task, data)
  File "/home/pspahwa/.local/lib/python3.6/site-packages/dask/core.py", line 121, in _execute_task
    return func(*(_execute_task(a, cache) for a in args))
  File "/home/pspahwa/.local/lib/python3.6/site-packages/dask/core.py", line 121, in <genexpr>
    return func(*(_execute_task(a, cache) for a in args))
  File "/home/pspahwa/.local/lib/python3.6/site-packages/dask/core.py", line 121, in _execute_task
    return func(*(_execute_task(a, cache) for a in args))
  File "/home/pspahwa/.local/lib/python3.6/site-packages/dask/dataframe/io/csv.py", line 156, in pandas_read_text
    coerce_dtypes(df, dtypes)
  File "/home/pspahwa/.local/lib/python3.6/site-packages/dask/dataframe/io/csv.py", line 260, in coerce_dtypes
    raise ValueError(msg)
ValueError: Mismatched dtypes found in `pd.read_csv`/`pd.read_table`.

+------------+--------+----------+
| Column     | Found  | Expected |
+------------+--------+----------+
| Check      | object | float64  |
| OtherName4 | object | float64  |
+------------+--------+----------+

The following columns also raised exceptions on conversion:

- Check
  ValueError("could not convert string to float: '1;2'",)
- OtherName4
  ValueError("could not convert string to float: 'WalMart'",)

Usually this is due to dask's dtype inference failing, and
*may* be fixed by specifying dtypes manually by adding:

dtype={'Check': 'object',
       'OtherName4': 'object'}

to the call to `read_csv`/`read_table`.

The above exception was the direct cause of the following exception:

Traceback (most recent call last):
  File "DirectSearch/updatedDS/possibleNamesDS.py", line 37, in <module>
    main(sys.argv[1], sys.argv[2])
  File "DirectSearch/updatedDS/possibleNamesDS.py", line 31, in main
    news_df["Firms Mentioned"] = news_df.apply(lambda x: find_firms_associated_with_news(x, all_company_lists), axis = 1)
  File "/home/pspahwa/.local/lib/python3.6/site-packages/dask/dataframe/core.py", line 4501, in apply
    M.apply, self._meta_nonempty, func, args=args, udf=True, **kwds
  File "/home/pspahwa/.local/lib/python3.6/site-packages/dask/dataframe/core.py", line 5332, in _emulate
    return func(*_extract_meta(args, True), **_extract_meta(kwargs, True))
  File "/apps/python/3.6/3.6.12/lib/python3.6/contextlib.py", line 99, in __exit__
    self.gen.throw(type, value, traceback)
  File "/home/pspahwa/.local/lib/python3.6/site-packages/dask/dataframe/utils.py", line 201, in raise_on_meta_error
    raise ValueError(msg) from e
ValueError: Metadata inference failed in `apply`.

You have supplied a custom function and Dask is unable to 
determine the type of output that that function returns. 

To resolve this please provide a meta= keyword.
The docstring of the Dask function you ran should have more information.

Original error is below:
------------------------
ValueError('Mismatched dtypes found in `pd.read_csv`/`pd.read_table`.\n\n+------------+--------+----------+\n| Column     | Found  | Expected |\n+------------+--------+----------+\n| Check      | object | float64  |\n| OtherName4 | object | float64  |\n+------------+--------+----------+\n\nThe following columns also raised exceptions on conversion:\n\n- Check\n  ValueError("could not convert string to float: \'1;2\'",)\n- OtherName4\n  ValueError("could not convert string to float: \'WalMart\'",)\n\nUsually this is due to dask\'s dtype inference failing, and\n*may* be fixed by specifying dtypes manually by adding:\n\ndtype={\'Check\': \'object\',\n       \'OtherName4\': \'object\'}\n\nto the call to `read_csv`/`read_table`.',)

Traceback:
---------
  File "/home/pspahwa/.local/lib/python3.6/site-packages/dask/dataframe/utils.py", line 180, in raise_on_meta_error
    yield
  File "/home/pspahwa/.local/lib/python3.6/site-packages/dask/dataframe/core.py", line 5332, in _emulate
    return func(*_extract_meta(args, True), **_extract_meta(kwargs, True))
  File "/home/pspahwa/.local/lib/python3.6/site-packages/dask/utils.py", line 901, in __call__
    return getattr(obj, self.method)(*args, **kwargs)
  File "/apps/python/3.6/3.6.12/lib/python3.6/site-packages/pandas/core/frame.py", line 7552, in apply
    return op.get_result()
  File "/apps/python/3.6/3.6.12/lib/python3.6/site-packages/pandas/core/apply.py", line 185, in get_result
    return self.apply_standard()
  File "/apps/python/3.6/3.6.12/lib/python3.6/site-packages/pandas/core/apply.py", line 276, in apply_standard
    results, res_index = self.apply_series_generator()
  File "/apps/python/3.6/3.6.12/lib/python3.6/site-packages/pandas/core/apply.py", line 305, in apply_series_generator
    results[i] = self.f(v)
  File "DirectSearch/updatedDS/possibleNamesDS.py", line 31, in <lambda>
    news_df["Firms Mentioned"] = news_df.apply(lambda x: find_firms_associated_with_news(x, all_company_lists), axis = 1)
  File "DirectSearch/updatedDS/possibleNamesDS.py", line 17, in find_firms_associated_with_news
    for company_list in all_company_lists:
  File "/home/pspahwa/.local/lib/python3.6/site-packages/dask/dataframe/core.py", line 3060, in __iter__
    s = self.get_partition(i).compute()
  File "/home/pspahwa/.local/lib/python3.6/site-packages/dask/base.py", line 283, in compute
    (result,) = compute(self, traverse=False, **kwargs)
  File "/home/pspahwa/.local/lib/python3.6/site-packages/dask/base.py", line 565, in compute
    results = schedule(dsk, keys, **kwargs)
  File "/home/pspahwa/.local/lib/python3.6/site-packages/dask/threaded.py", line 84, in get
    **kwargs
  File "/home/pspahwa/.local/lib/python3.6/site-packages/dask/local.py", line 487, in get_async
    raise_exception(exc, tb)
  File "/home/pspahwa/.local/lib/python3.6/site-packages/dask/local.py", line 317, in reraise
    raise exc
  File "/home/pspahwa/.local/lib/python3.6/site-packages/dask/local.py", line 222, in execute_task
    result = _execute_task(task, data)
  File "/home/pspahwa/.local/lib/python3.6/site-packages/dask/core.py", line 121, in _execute_task
    return func(*(_execute_task(a, cache) for a in args))
  File "/home/pspahwa/.local/lib/python3.6/site-packages/dask/core.py", line 121, in <genexpr>
    return func(*(_execute_task(a, cache) for a in args))
  File "/home/pspahwa/.local/lib/python3.6/site-packages/dask/core.py", line 121, in _execute_task
    return func(*(_execute_task(a, cache) for a in args))
  File "/home/pspahwa/.local/lib/python3.6/site-packages/dask/dataframe/io/csv.py", line 156, in pandas_read_text
    coerce_dtypes(df, dtypes)
  File "/home/pspahwa/.local/lib/python3.6/site-packages/dask/dataframe/io/csv.py", line 260, in coerce_dtypes
    raise ValueError(msg)

srun: error: mcn03: task 0: Exited with exit code 1
