==========================================
SLURM_JOB_ID = 8540137
SLURM_SUBMIT_DIR = /project/kh_mercury_1/CriCount
SLURM_JOB_NODELIST = mcn34
==========================================
Job ID: 8540137
Job User: pspahwa
Num Cores: 16
/home/pspahwa/.local/lib/python3.6/site-packages/dask/dataframe/core.py:4503: UserWarning: 
You did not provide metadata, so Dask is running your function on a small dataset to guess output types. It is possible that Dask will guess incorrectly.
To provide an explicit output types or to silence this message, please provide the `meta=` keyword, as described in the map or apply function that you are using.
  Before: .apply(func)
  After:  .apply(func, meta=(None, 'object'))

  warnings.warn(meta_warning(meta))
Traceback (most recent call last):
  File "/home/pspahwa/.local/lib/python3.6/site-packages/dask/dataframe/utils.py", line 180, in raise_on_meta_error
    yield
  File "/home/pspahwa/.local/lib/python3.6/site-packages/dask/dataframe/core.py", line 5332, in _emulate
    return func(*_extract_meta(args, True), **_extract_meta(kwargs, True))
  File "/home/pspahwa/.local/lib/python3.6/site-packages/dask/utils.py", line 901, in __call__
    return getattr(obj, self.method)(*args, **kwargs)
  File "/apps/python/3.6/3.6.12/lib/python3.6/site-packages/pandas/core/series.py", line 4213, in apply
    mapped = lib.map_infer(values, f, convert=convert_dtype)
  File "pandas/_libs/lib.pyx", line 2403, in pandas._libs.lib.map_infer
  File "fuzzyMatchCC.py", line 48, in <lambda>
    results = entity_df["Cleansed_Name"].apply(lambda x: process.extractOne(x, choices, scorer=fuzz.ratio)).to_frame()
  File "cpp_process.pyx", line 637, in cpp_process.extractOne
  File "cpp_process.pyx", line 323, in cpp_process.extractOne_list
  File "/home/pspahwa/.local/lib/python3.6/site-packages/dask/dataframe/core.py", line 3060, in __iter__
    s = self.get_partition(i).compute()
  File "/home/pspahwa/.local/lib/python3.6/site-packages/dask/base.py", line 283, in compute
    (result,) = compute(self, traverse=False, **kwargs)
  File "/home/pspahwa/.local/lib/python3.6/site-packages/dask/base.py", line 565, in compute
    results = schedule(dsk, keys, **kwargs)
  File "/home/pspahwa/.local/lib/python3.6/site-packages/dask/threaded.py", line 84, in get
    **kwargs
  File "/home/pspahwa/.local/lib/python3.6/site-packages/dask/local.py", line 487, in get_async
    raise_exception(exc, tb)
  File "/home/pspahwa/.local/lib/python3.6/site-packages/dask/local.py", line 317, in reraise
    raise exc
  File "/home/pspahwa/.local/lib/python3.6/site-packages/dask/local.py", line 222, in execute_task
    result = _execute_task(task, data)
  File "/home/pspahwa/.local/lib/python3.6/site-packages/dask/core.py", line 121, in _execute_task
    return func(*(_execute_task(a, cache) for a in args))
  File "/home/pspahwa/.local/lib/python3.6/site-packages/dask/core.py", line 121, in <genexpr>
    return func(*(_execute_task(a, cache) for a in args))
  File "/home/pspahwa/.local/lib/python3.6/site-packages/dask/core.py", line 121, in _execute_task
    return func(*(_execute_task(a, cache) for a in args))
  File "/home/pspahwa/.local/lib/python3.6/site-packages/dask/dataframe/io/csv.py", line 156, in pandas_read_text
    coerce_dtypes(df, dtypes)
  File "/home/pspahwa/.local/lib/python3.6/site-packages/dask/dataframe/io/csv.py", line 260, in coerce_dtypes
    raise ValueError(msg)
ValueError: Mismatched dtypes found in `pd.read_csv`/`pd.read_table`.

+-----------+---------+----------+
| Column    | Found   | Expected |
+-----------+---------+----------+
| companyid | float64 | int64    |
+-----------+---------+----------+

Usually this is due to dask's dtype inference failing, and
*may* be fixed by specifying dtypes manually by adding:

dtype={'companyid': 'float64'}

to the call to `read_csv`/`read_table`.

Alternatively, provide `assume_missing=True` to interpret
all unspecified integer columns as floats.

The above exception was the direct cause of the following exception:

Traceback (most recent call last):
  File "fuzzyMatchCC.py", line 53, in <module>
    main()
  File "fuzzyMatchCC.py", line 48, in main
    results = entity_df["Cleansed_Name"].apply(lambda x: process.extractOne(x, choices, scorer=fuzz.ratio)).to_frame()
  File "/home/pspahwa/.local/lib/python3.6/site-packages/dask/dataframe/core.py", line 3368, in apply
    **kwds,
  File "/home/pspahwa/.local/lib/python3.6/site-packages/dask/dataframe/core.py", line 5332, in _emulate
    return func(*_extract_meta(args, True), **_extract_meta(kwargs, True))
  File "/apps/python/3.6/3.6.12/lib/python3.6/contextlib.py", line 99, in __exit__
    self.gen.throw(type, value, traceback)
  File "/home/pspahwa/.local/lib/python3.6/site-packages/dask/dataframe/utils.py", line 201, in raise_on_meta_error
    raise ValueError(msg) from e
ValueError: Metadata inference failed in `apply`.

You have supplied a custom function and Dask is unable to 
determine the type of output that that function returns. 

To resolve this please provide a meta= keyword.
The docstring of the Dask function you ran should have more information.

Original error is below:
------------------------
ValueError("Mismatched dtypes found in `pd.read_csv`/`pd.read_table`.\n\n+-----------+---------+----------+\n| Column    | Found   | Expected |\n+-----------+---------+----------+\n| companyid | float64 | int64    |\n+-----------+---------+----------+\n\nUsually this is due to dask's dtype inference failing, and\n*may* be fixed by specifying dtypes manually by adding:\n\ndtype={'companyid': 'float64'}\n\nto the call to `read_csv`/`read_table`.\n\nAlternatively, provide `assume_missing=True` to interpret\nall unspecified integer columns as floats.",)

Traceback:
---------
  File "/home/pspahwa/.local/lib/python3.6/site-packages/dask/dataframe/utils.py", line 180, in raise_on_meta_error
    yield
  File "/home/pspahwa/.local/lib/python3.6/site-packages/dask/dataframe/core.py", line 5332, in _emulate
    return func(*_extract_meta(args, True), **_extract_meta(kwargs, True))
  File "/home/pspahwa/.local/lib/python3.6/site-packages/dask/utils.py", line 901, in __call__
    return getattr(obj, self.method)(*args, **kwargs)
  File "/apps/python/3.6/3.6.12/lib/python3.6/site-packages/pandas/core/series.py", line 4213, in apply
    mapped = lib.map_infer(values, f, convert=convert_dtype)
  File "pandas/_libs/lib.pyx", line 2403, in pandas._libs.lib.map_infer
  File "fuzzyMatchCC.py", line 48, in <lambda>
    results = entity_df["Cleansed_Name"].apply(lambda x: process.extractOne(x, choices, scorer=fuzz.ratio)).to_frame()
  File "cpp_process.pyx", line 637, in cpp_process.extractOne
  File "cpp_process.pyx", line 323, in cpp_process.extractOne_list
  File "/home/pspahwa/.local/lib/python3.6/site-packages/dask/dataframe/core.py", line 3060, in __iter__
    s = self.get_partition(i).compute()
  File "/home/pspahwa/.local/lib/python3.6/site-packages/dask/base.py", line 283, in compute
    (result,) = compute(self, traverse=False, **kwargs)
  File "/home/pspahwa/.local/lib/python3.6/site-packages/dask/base.py", line 565, in compute
    results = schedule(dsk, keys, **kwargs)
  File "/home/pspahwa/.local/lib/python3.6/site-packages/dask/threaded.py", line 84, in get
    **kwargs
  File "/home/pspahwa/.local/lib/python3.6/site-packages/dask/local.py", line 487, in get_async
    raise_exception(exc, tb)
  File "/home/pspahwa/.local/lib/python3.6/site-packages/dask/local.py", line 317, in reraise
    raise exc
  File "/home/pspahwa/.local/lib/python3.6/site-packages/dask/local.py", line 222, in execute_task
    result = _execute_task(task, data)
  File "/home/pspahwa/.local/lib/python3.6/site-packages/dask/core.py", line 121, in _execute_task
    return func(*(_execute_task(a, cache) for a in args))
  File "/home/pspahwa/.local/lib/python3.6/site-packages/dask/core.py", line 121, in <genexpr>
    return func(*(_execute_task(a, cache) for a in args))
  File "/home/pspahwa/.local/lib/python3.6/site-packages/dask/core.py", line 121, in _execute_task
    return func(*(_execute_task(a, cache) for a in args))
  File "/home/pspahwa/.local/lib/python3.6/site-packages/dask/dataframe/io/csv.py", line 156, in pandas_read_text
    coerce_dtypes(df, dtypes)
  File "/home/pspahwa/.local/lib/python3.6/site-packages/dask/dataframe/io/csv.py", line 260, in coerce_dtypes
    raise ValueError(msg)

srun: error: mcn34: task 0: Exited with exit code 1
